2023-08-31 21:04:20,237 - main - ERROR - Exception on /verify-email [POST]
Traceback (most recent call last):
  File "C:\Users\amarl\dev\bill-the-ai\bill-the-ai\.venv\lib\site-packages\sqlalchemy\engine\base.py", line 1965, in _exec_single_context
    self.dialect.do_execute(
  File "C:\Users\amarl\dev\bill-the-ai\bill-the-ai\.venv\lib\site-packages\sqlalchemy\engine\default.py", line 921, in do_execute
    cursor.execute(statement, parameters)
psycopg2.errors.InvalidTextRepresentation: invalid input syntax for type uuid: "fe70b6e1-bfa2-4fe5-8212-35d25a77073"
LINE 1: ...l = 'amarlar2354@gmail.com' and verification_id = 'fe70b6e1-...
                                                             ^


The above exception was the direct cause of the following exception:

Traceback (most recent call last):
  File "C:\Users\amarl\dev\bill-the-ai\bill-the-ai\.venv\lib\site-packages\flask\app.py", line 2190, in wsgi_app
    response = self.full_dispatch_request()
  File "C:\Users\amarl\dev\bill-the-ai\bill-the-ai\.venv\lib\site-packages\flask\app.py", line 1486, in full_dispatch_request
    rv = self.handle_user_exception(e)
  File "C:\Users\amarl\dev\bill-the-ai\bill-the-ai\.venv\lib\site-packages\flask_cors\extension.py", line 176, in wrapped_function
    return cors_after_request(app.make_response(f(*args, **kwargs)))
  File "C:\Users\amarl\dev\bill-the-ai\bill-the-ai\.venv\lib\site-packages\flask\app.py", line 1484, in full_dispatch_request
    rv = self.dispatch_request()
  File "C:\Users\amarl\dev\bill-the-ai\bill-the-ai\.venv\lib\site-packages\flask\app.py", line 1469, in dispatch_request
    return self.ensure_sync(self.view_functions[rule.endpoint])(**view_args)
  File "C:\Users\amarl\dev\bill-the-ai\bill-the-ai\main.py", line 126, in verify_email
    result = conn.execute(query)
  File "C:\Users\amarl\dev\bill-the-ai\bill-the-ai\.venv\lib\site-packages\sqlalchemy\engine\base.py", line 1412, in execute
    return meth(
  File "C:\Users\amarl\dev\bill-the-ai\bill-the-ai\.venv\lib\site-packages\sqlalchemy\sql\elements.py", line 515, in _execute_on_connection
    return connection._execute_clauseelement(
  File "C:\Users\amarl\dev\bill-the-ai\bill-the-ai\.venv\lib\site-packages\sqlalchemy\engine\base.py", line 1635, in _execute_clauseelement
    ret = self._execute_context(
  File "C:\Users\amarl\dev\bill-the-ai\bill-the-ai\.venv\lib\site-packages\sqlalchemy\engine\base.py", line 1844, in _execute_context
    return self._exec_single_context(
  File "C:\Users\amarl\dev\bill-the-ai\bill-the-ai\.venv\lib\site-packages\sqlalchemy\engine\base.py", line 1984, in _exec_single_context
    self._handle_dbapi_exception(
  File "C:\Users\amarl\dev\bill-the-ai\bill-the-ai\.venv\lib\site-packages\sqlalchemy\engine\base.py", line 2339, in _handle_dbapi_exception
    raise sqlalchemy_exception.with_traceback(exc_info[2]) from e
  File "C:\Users\amarl\dev\bill-the-ai\bill-the-ai\.venv\lib\site-packages\sqlalchemy\engine\base.py", line 1965, in _exec_single_context
    self.dialect.do_execute(
  File "C:\Users\amarl\dev\bill-the-ai\bill-the-ai\.venv\lib\site-packages\sqlalchemy\engine\default.py", line 921, in do_execute
    cursor.execute(statement, parameters)
sqlalchemy.exc.DataError: (psycopg2.errors.InvalidTextRepresentation) invalid input syntax for type uuid: "fe70b6e1-bfa2-4fe5-8212-35d25a77073"
LINE 1: ...l = 'amarlar2354@gmail.com' and verification_id = 'fe70b6e1-...
                                                             ^

[SQL: SELECT * FROM bill_update_subscribers WHERE email = %(email)s and verification_id = %(id)s]
[parameters: {'email': 'amarlar2354@gmail.com', 'id': 'fe70b6e1-bfa2-4fe5-8212-35d25a77073'}]
(Background on this error at: https://sqlalche.me/e/20/9h9h)
2023-08-31 21:07:44,158 - main - ERROR - Exception on /verify-email [POST]
Traceback (most recent call last):
  File "C:\Users\amarl\dev\bill-the-ai\bill-the-ai\.venv\lib\site-packages\sqlalchemy\engine\base.py", line 1965, in _exec_single_context
    self.dialect.do_execute(
  File "C:\Users\amarl\dev\bill-the-ai\bill-the-ai\.venv\lib\site-packages\sqlalchemy\engine\default.py", line 921, in do_execute
    cursor.execute(statement, parameters)
psycopg2.errors.InvalidTextRepresentation: invalid input syntax for type uuid: "fe70b6e1-bfa2-4fe5-8212-35d25a77073"
LINE 1: ...l = 'amarlar2354@gmail.com' and verification_id = 'fe70b6e1-...
                                                             ^


The above exception was the direct cause of the following exception:

Traceback (most recent call last):
  File "C:\Users\amarl\dev\bill-the-ai\bill-the-ai\.venv\lib\site-packages\flask\app.py", line 2190, in wsgi_app
    response = self.full_dispatch_request()
  File "C:\Users\amarl\dev\bill-the-ai\bill-the-ai\.venv\lib\site-packages\flask\app.py", line 1486, in full_dispatch_request
    rv = self.handle_user_exception(e)
  File "C:\Users\amarl\dev\bill-the-ai\bill-the-ai\.venv\lib\site-packages\flask_cors\extension.py", line 176, in wrapped_function
    return cors_after_request(app.make_response(f(*args, **kwargs)))
  File "C:\Users\amarl\dev\bill-the-ai\bill-the-ai\.venv\lib\site-packages\flask\app.py", line 1484, in full_dispatch_request
    rv = self.dispatch_request()
  File "C:\Users\amarl\dev\bill-the-ai\bill-the-ai\.venv\lib\site-packages\flask\app.py", line 1469, in dispatch_request
    return self.ensure_sync(self.view_functions[rule.endpoint])(**view_args)
  File "C:\Users\amarl\dev\bill-the-ai\bill-the-ai\main.py", line 126, in verify_email
    result = conn.execute(query)
  File "C:\Users\amarl\dev\bill-the-ai\bill-the-ai\.venv\lib\site-packages\sqlalchemy\engine\base.py", line 1412, in execute
    return meth(
  File "C:\Users\amarl\dev\bill-the-ai\bill-the-ai\.venv\lib\site-packages\sqlalchemy\sql\elements.py", line 515, in _execute_on_connection
    return connection._execute_clauseelement(
  File "C:\Users\amarl\dev\bill-the-ai\bill-the-ai\.venv\lib\site-packages\sqlalchemy\engine\base.py", line 1635, in _execute_clauseelement
    ret = self._execute_context(
  File "C:\Users\amarl\dev\bill-the-ai\bill-the-ai\.venv\lib\site-packages\sqlalchemy\engine\base.py", line 1844, in _execute_context
    return self._exec_single_context(
  File "C:\Users\amarl\dev\bill-the-ai\bill-the-ai\.venv\lib\site-packages\sqlalchemy\engine\base.py", line 1984, in _exec_single_context
    self._handle_dbapi_exception(
  File "C:\Users\amarl\dev\bill-the-ai\bill-the-ai\.venv\lib\site-packages\sqlalchemy\engine\base.py", line 2339, in _handle_dbapi_exception
    raise sqlalchemy_exception.with_traceback(exc_info[2]) from e
  File "C:\Users\amarl\dev\bill-the-ai\bill-the-ai\.venv\lib\site-packages\sqlalchemy\engine\base.py", line 1965, in _exec_single_context
    self.dialect.do_execute(
  File "C:\Users\amarl\dev\bill-the-ai\bill-the-ai\.venv\lib\site-packages\sqlalchemy\engine\default.py", line 921, in do_execute
    cursor.execute(statement, parameters)
sqlalchemy.exc.DataError: (psycopg2.errors.InvalidTextRepresentation) invalid input syntax for type uuid: "fe70b6e1-bfa2-4fe5-8212-35d25a77073"
LINE 1: ...l = 'amarlar2354@gmail.com' and verification_id = 'fe70b6e1-...
                                                             ^

[SQL: SELECT * FROM bill_update_subscribers WHERE email = %(email)s and verification_id = %(id)s]
[parameters: {'email': 'amarlar2354@gmail.com', 'id': 'fe70b6e1-bfa2-4fe5-8212-35d25a77073'}]
(Background on this error at: https://sqlalche.me/e/20/9h9h)
2023-08-31 21:08:35,081 - main - ERROR - Exception on /verify-email [POST]
Traceback (most recent call last):
  File "C:\Users\amarl\dev\bill-the-ai\bill-the-ai\.venv\lib\site-packages\sqlalchemy\engine\base.py", line 1965, in _exec_single_context
    self.dialect.do_execute(
  File "C:\Users\amarl\dev\bill-the-ai\bill-the-ai\.venv\lib\site-packages\sqlalchemy\engine\default.py", line 921, in do_execute
    cursor.execute(statement, parameters)
psycopg2.errors.InvalidTextRepresentation: invalid input syntax for type uuid: "fe70b6e1-bfa2-4fe5-8212-35d25a77073"
LINE 1: ...l = 'amarlar2354@gmail.com' and verification_id = 'fe70b6e1-...
                                                             ^


The above exception was the direct cause of the following exception:

Traceback (most recent call last):
  File "C:\Users\amarl\dev\bill-the-ai\bill-the-ai\.venv\lib\site-packages\flask\app.py", line 2190, in wsgi_app
    response = self.full_dispatch_request()
  File "C:\Users\amarl\dev\bill-the-ai\bill-the-ai\.venv\lib\site-packages\flask\app.py", line 1486, in full_dispatch_request
    rv = self.handle_user_exception(e)
  File "C:\Users\amarl\dev\bill-the-ai\bill-the-ai\.venv\lib\site-packages\flask_cors\extension.py", line 176, in wrapped_function
    return cors_after_request(app.make_response(f(*args, **kwargs)))
  File "C:\Users\amarl\dev\bill-the-ai\bill-the-ai\.venv\lib\site-packages\flask\app.py", line 1484, in full_dispatch_request
    rv = self.dispatch_request()
  File "C:\Users\amarl\dev\bill-the-ai\bill-the-ai\.venv\lib\site-packages\flask\app.py", line 1469, in dispatch_request
    return self.ensure_sync(self.view_functions[rule.endpoint])(**view_args)
  File "C:\Users\amarl\dev\bill-the-ai\bill-the-ai\main.py", line 126, in verify_email
    result = conn.execute(query)
  File "C:\Users\amarl\dev\bill-the-ai\bill-the-ai\.venv\lib\site-packages\sqlalchemy\engine\base.py", line 1412, in execute
    return meth(
  File "C:\Users\amarl\dev\bill-the-ai\bill-the-ai\.venv\lib\site-packages\sqlalchemy\sql\elements.py", line 515, in _execute_on_connection
    return connection._execute_clauseelement(
  File "C:\Users\amarl\dev\bill-the-ai\bill-the-ai\.venv\lib\site-packages\sqlalchemy\engine\base.py", line 1635, in _execute_clauseelement
    ret = self._execute_context(
  File "C:\Users\amarl\dev\bill-the-ai\bill-the-ai\.venv\lib\site-packages\sqlalchemy\engine\base.py", line 1844, in _execute_context
    return self._exec_single_context(
  File "C:\Users\amarl\dev\bill-the-ai\bill-the-ai\.venv\lib\site-packages\sqlalchemy\engine\base.py", line 1984, in _exec_single_context
    self._handle_dbapi_exception(
  File "C:\Users\amarl\dev\bill-the-ai\bill-the-ai\.venv\lib\site-packages\sqlalchemy\engine\base.py", line 2339, in _handle_dbapi_exception
    raise sqlalchemy_exception.with_traceback(exc_info[2]) from e
  File "C:\Users\amarl\dev\bill-the-ai\bill-the-ai\.venv\lib\site-packages\sqlalchemy\engine\base.py", line 1965, in _exec_single_context
    self.dialect.do_execute(
  File "C:\Users\amarl\dev\bill-the-ai\bill-the-ai\.venv\lib\site-packages\sqlalchemy\engine\default.py", line 921, in do_execute
    cursor.execute(statement, parameters)
sqlalchemy.exc.DataError: (psycopg2.errors.InvalidTextRepresentation) invalid input syntax for type uuid: "fe70b6e1-bfa2-4fe5-8212-35d25a77073"
LINE 1: ...l = 'amarlar2354@gmail.com' and verification_id = 'fe70b6e1-...
                                                             ^

[SQL: SELECT * FROM bill_update_subscribers WHERE email = %(email)s and verification_id = %(id)s]
[parameters: {'email': 'amarlar2354@gmail.com', 'id': 'fe70b6e1-bfa2-4fe5-8212-35d25a77073'}]
(Background on this error at: https://sqlalche.me/e/20/9h9h)
